Workbook

Sheet 00_Instrucciones
A1: Plantilla Bloomberg — Reporte Mensual de Tasas Mercantil
A3: Que es esto
A4: Plantilla que se corre cada mes para extraer datos de Bloomberg al cierre del ultimo dia habil.
A5: Output: este mismo archivo con valores cuajados (no formulas vivas).
A7: LECCION DEL PROYECTO HERMANO (mercantil-saa) — IMPORTANTE
A8: NO usar 'today' como string en formulas BDH (=BDH(...,'today',...)).
A9: NO usar =TODAY() en ninguna celda del archivo.
A10: Ambos se RECALCULAN al reabrir el archivo y rompen la reproducibilidad: los datos del
A11: snapshot del cierre de mes pueden mutarse a la fecha en que alguien lo abre semanas despues.
A12: La plantilla esta diseñada para evitar esto: todas las formulas referencian la celda AS_OF de
A13: la hoja 01_Parametros, que es input manual fijo. Aun asi, el paso de Paste Special -> Values
A14: antes de devolver el archivo es OBLIGATORIO. Vea el paso 9 abajo.
... A55: Total: ~5 minutos por corte.

Sheet 01_Parametros
A1: Parametros del corte
A2: Parametro | B2: Valor | C2: Tipo | D2: Descripcion
A3: AS_OF | C3: input | D3: Ultimo dia habil del mes a reportar — EDITAR esta celda
A4: MES_REPORTE | B4: =TEXT(B3,"yyyy-mm") | C4: auto | D4: YYYY-MM del corte
A5: MES_ANT | B5: =EOMONTH(B3,-1) | C5: auto | D5: Ultimo dia del mes anterior
A6: YE_ANT | B6: =DATE(YEAR(B3)-1,12,31) | C6: auto | D6: 31-dic del año anterior
A7: INI_12M | B7: =EDATE(B3,-12) | C7: auto | D7: 12 meses antes de AS_OF
A8: ANALISTA | C8: input | D8: Nombre del analista que corre la plantilla
A9: FECHA_CARGA | C9: input | D9: Fecha en que se cargaron los datos — ESCRIBIR a mano (NO =TODAY())
A10: FECHA_GUARDADO_VALUES | C10: input | D10: Fecha en que se hizo Paste Special -> Values — ESCRIBIR a mano
A11: BBG_UUID | C11: input | D11: BBG UUID (opcional)
A12: NOTAS_RAPIDAS | C12: input | D12: Cualquier anomalia detectada al cargar

Sheet 02_Datos
A1: # | B1: categoria | C1: region | D1: instrument | E1: tenor_label | F1: tenor_years | G1: ticker | H1: field | I1: unit | J1: val_AS_OF | K1: val_MES_ANT | L1: val_YE_ANT | M1: val_INI_12M | N1: nota
A2: 1 | B2: policy | C2: US | D2: FED_FUNDS_UPPER | E2: — | F2: 0 | G2: FDTR Index | H2: PX_LAST | I2: percent | J2: =IFERROR(INDEX(BDH($G$2,$H$2,'01_Parametros'!$B$3,'01_Parametros'!$B$3,"Days=A","Fill=B","Dir=H"),1,2),BDH($G$2,$H$2,'01_Parametros'!$B$3,'01_Parametros'!$B$3,"Days=A","Fill=B")) | K2: =IFERROR(INDEX(BDH($G$2,$H$2,'01_Parametros'!$B$5,'01_Parametros'!$B$5,"Days=A","Fill=B","Dir=H"),1,2),BDH($G$2,$H$2,'01_Parametros'!$B$5,'01_Parametros'!$B$5,"Days=A","Fill=B")) | L2: =IFERROR(INDEX(BDH($G$2,$H$2,'01_Parametros'!$B$6,'01_Parametros'!$B$6,"Days=A","Fill=B","Dir=H"),1,2),BDH($G$2,$H$2,'01_Parametros'!$B$6,'01_Parametros'!$B$6,"Days=A","Fill=B")) | M2: =IFERROR(INDEX(BDH($G$2,$H$2,'01_Parametros'!$B$7,'01_Parametros'!$B$7,"Days=A","Fill=B","Dir=H"),1,2),BDH($G$2,$H$2,'01_Parametros'!$B$7,'01_Parametros'!$B$7,"Days=A","Fill=B")) | N2: Fed Funds Target Upper Bound
A3: 2 | B3: policy | C3: US | D3: FED_FUNDS_LOWER | E3: — | F3: 0 | G3: FDFD Index | H3: PX_LAST | I3: percent | J3: =IFERROR(INDEX(BDH($G$3,$H$3,'01_Parametros'!$B$3,'01_Parametros'!$B$3,"Days=A","Fill=B","Dir=H"),1,2),BDH($G$3,$H$3,'01_Parametros'!$B$3,'01_Parametros'!$B$3,"Days=A","Fill=B")) | K3: =IFERROR(INDEX(BDH($G$3,$H$3,'01_Parametros'!$B$5,'01_Parametros'!$B$5,"Days=A","Fill=B","Dir=H"),1,2),BDH($G$3,$H$3,'01_Parametros'!$B$5,'01_Parametros'!$B$5,"Days=A","Fill=B")) | L3: =IFERROR(INDEX(BDH($G$3,$H$3,'01_Parametros'!$B$6,'01_Parametros'!$B$6,"Days=A","Fill=B","Dir=H"),1,2),BDH($G$3,$H$3,'01_Parametros'!$B$6,'01_Parametros'!$B$6,"Days=A","Fill=B")) | M3: =IFERROR(INDEX(BDH($G$3,$H$3,'01_Parametros'!$B$7,'01_Parametros'!$B$7,"Days=A","Fill=B","Dir=H"),1,2),BDH($G$3,$H$3,'01_Parametros'!$B$7,'01_Parametros'!$B$7,"Days=A","Fill=B")) | N3: Fed Funds Target Lower Bound — confirmar ticker
A4: 3 | B4: policy | C4: US | D4: EFFR | E4: ON | F4: 0 | G4: FEDL01 Index | H4: PX_LAST | I4: percent | J4: =IFERROR(INDEX(BDH($G$4,$H$4,'01_Parametros'!$B$3,'01_Parametros'!$B$3,"Days=A","Fill=B","Dir=H"),1,2),BDH($G$4,$H$4,'01_Parametros'!$B$3,'01_Parametros'!$B$3,"Days=A","Fill=B")) | K4: =IFERROR(INDEX(BDH($G$4,$H$4,'01_Parametros'!$B$5,'01_Parametros'!$B$5,"Days=A","Fill=B","Dir=H"),1,2),BDH($G$4,$H$4,'01_Parametros'!$B$5,'01_Parametros'!$B$5,"Days=A","Fill=B")) | L4: =IFERROR(INDEX(BDH($G$4,$H$4,'01_Parametros'!$B$6,'01_Parametros'!$B$6,"Days=A","Fill=B","Dir=H"),1,2),BDH($G$4,$H$4,'01_Parametros'!$B$6,'01_Parametros'!$B$6,"Days=A","Fill=B")) | M4: =IFERROR(INDEX(BDH($G$4,$H$4,'01_Parametros'!$B$7,'01_Parametros'!$B$7,"Days=A","Fill=B","Dir=H"),1,2),BDH($G$4,$H$4,'01_Parametros'!$B$7,'01_Parametros'!$B$7,"Days=A","Fill=B")) | N4: Effective Fed Funds Rate
A5: 4 | B5: policy | C5: US | D5: IORB | E5: — | F5: 0 | G5: FRRRIORB Index | H5: PX_LAST | I5: percent | J5: =IFERROR(INDEX(BDH($G$5,$H$5,'01_Parametros'!$B$3,'01_Parametros'!$B$3,"Days=A","Fill=B","Dir=H"),1,2),BDH($G$5,$H$5,'01_Parametros'!$B$3,'01_Parametros'!$B$3,"Days=A","Fill=B")) | K5: =IFERROR(INDEX(BDH($G$5,$H$5,'01_Parametros'!$B$5,'01_Parametros'!$B$5,"Days=A","Fill=B","Dir=H"),1,2),BDH($G$5,$H$5,'01_Parametros'!$B$5,'01_Parametros'!$B$5,"Days=A","Fill=B")) | L5: =IFERROR(INDEX(BDH($G$5,$H$5,'01_Parametros'!$B$6,'01_Parametros'!$B$6,"Days=A","Fill=B","Dir=H"),1,2),BDH($G$5,$H$5,'01_Parametros'!$B$6,'01_Parametros'!$B$6,"Days=A","Fill=B")) | M5: =IFERROR(INDEX(BDH($G$5,$H$5,'01_Parametros'!$B$7,'01_Parametros'!$B$7,"Days=A","Fill=B","Dir=H"),1,2),BDH($G$5,$H$5,'01_Parametros'!$B$7,'01_Parametros'!$B$7,"Days=A","Fill=B")) | N5: Interest on Reserve Balances
A6: 5 | B6: policy | C6: US | D6: ON_RRP | E6: ON | F6: 0 | G6: RRPONTSY Index | H6: PX_LAST | I6: percent | J6: =IFERROR(INDEX(BDH($G$6,$H$6,'01_Parametros'!$B$3,'01_Parametros'!$B$3,"Days=A","Fill=B","Dir=H"),1,2),BDH($G$6,$H$6,'01_Parametros'!$B$3,'01_Parametros'!$B$3,"Days=A","Fill=B")) | K6: =IFERROR(INDEX(BDH($G$6,$H$6,'01_Parametros'!$B$5,'01_Parametros'!$B$5,"Days=A","Fill=B","Dir=H"),1,2),BDH($G$6,$H$6,'01_Parametros'!$B$5,'01_Parametros'!$B$5,"Days=A","Fill=B")) | L6: =IFERROR(INDEX(BDH($G$6,$H$6,'01_Parametros'!$B$6,'01_Parametros'!$B$6,"Days=A","Fill=B","Dir=H"),1,2),BDH($G$6,$H$6,'01_Parametros'!$B$6,'01_Parametros'!$B$6,"Days=A","Fill=B")) | M6: =IFERROR(INDEX(BDH($G$6,$H$6,'01_Parametros'!$B$7,'01_Parametros'!$B$7,"Days=A","Fill=B","Dir=H"),1,2),BDH($G$6,$H$6,'01_Parametros'!$B$7,'01_Parametros'!$B$7,"Days=A","Fill=B")) | N6: Overnight Reverse Repo
A7: 6 | B7: money_market | C7: US | D7: SOFR_ON | E7: ON | F7: 0.003 | G7: SOFRRATE Index | H7: PX_LAST | I7: percent | J7: =IFERROR(INDEX(BDH($G$7,$H$7,'01_Parametros'!$B$3,'01_Parametros'!$B$3,"Days=A","Fill=B","Dir=H"),1,2),BDH($G$7,$H$7,'01_Parametros'!$B$3,'01_Parametros'!$B$3,"Days=A","Fill=B")) | K7: =IFERROR(INDEX(BDH($G$7,$H$7,'01_Parametros'!$B$5,'01_Parametros'!$B$5,"Days=A","Fill=B","Dir=H"),1,2),BDH($G$7,$H$7,'01_Parametros'!$B$5,'01_Parametros'!$B$5,"Days=A","Fill=B")) | L7: =IFERROR(INDEX(BDH($G$7,$H$7,'01_Parametros'!$B$6,'01_Parametros'!$B$6,"Days=A","Fill=B","Dir=H"),1,2),BDH($G$7,$H$7,'01_Parametros'!$B$6,'01_Parametros'!$B$6,"Days=A","Fill=B")) | M7: =IFERROR(INDEX(BDH($G$7,$H$7,'01_Parametros'!$B$7,'01_Parametros'!$B$7,"Days=A","Fill=B","Dir=H"),1,2),BDH($G$7,$H$7,'01_Parametros'!$B$7,'01_Parametros'!$B$7,"Days=A","Fill=B")) | N7: SOFR overnight
A8: 7 | B8: money_market | C8: US | D8: SOFR_1M_AVG | E8: 1M_AVG | F8: 0.083 | G8: SOFR30A Index | H8: PX_LAST | I8: percent | J8: =IFERROR(INDEX(BDH($G$8,$H$8,'01_Parametros'!$B$3,'01_Parametros'!$B$3,"Days=A","Fill=B","Dir=H"),1,2),BDH($G$8,$H$8,'01_Parametros'!$B$3,'01_Parametros'!$B$3,"Days=A","Fill=B")) | K8: =IFERROR(INDEX(BDH($G$8,$H$8,'01_Parametros'!$B$5,'01_Parametros'!$B$5,"Days=A","Fill=B","Dir=H"),1,2),BDH($G$8,$H$8,'01_Parametros'!$B$5,'01_Parametros'!$B$5,"Days=A","Fill=B")) | L8: =IFERROR(INDEX(BDH($G$8,$H$8,'01_Parametros'!$B$6,'01_Parametros'!$B$6,"Days=A","Fill=B","Dir=H"),1,2),BDH($G$8,$H$8,'01_Parametros'!$B$6,'01_Parametros'!$B$6,"Days=A","Fill=B")) | M8: =IFERROR(INDEX(BDH($G$8,$H$8,'01_Parametros'!$B$7,'01_Parametros'!$B$7,"Days=A","Fill=B","Dir=H"),1,2),BDH($G$8,$H$8,'01_Parametros'!$B$7,'01_Parametros'!$B$7,"Days=A","Fill=B")) | N8: SOFR 30-day average
A9: 8 | B9: money_market | C9: US | D9: SOFR_3M_AVG | E9: 3M_AVG | F9: 0.25 | G9: SOFR90A Index | H9: PX_LAST | I9: percent | J9: =IFERROR(INDEX(BDH($G$9,$H$9,'01_Parametros'!$B$3,'01_Parametros'!$B$3,"Days=A","Fill=B","Dir=H"),1,2),BDH($G$9,$H$9,'01_Parametros'!$B$3,'01_Parametros'!$B$3,"Days=A","Fill=B")) | K9: =IFERROR(INDEX(BDH($G$9,$H$9,'01_Parametros'!$B$5,'01_Parametros'!$B$5,"Days=A","Fill=B","Dir=H"),1,2),BDH($G$9,$H$9,'01_Parametros'!$B$5,'01_Parametros'!$B$5,"Days=A","Fill=B")) | L9: =IFERROR(INDEX(BDH($G$9,$H$9,'01_Parametros'!$B$6,'01_Parametros'!$B$6,"Days=A","Fill=B","Dir=H"),1,2),BDH($G$9,$H$9,'01_Parametros'!$B$6,'01_Parametros'!$B$6,"Days=A","Fill=B")) | M9: =IFERROR(INDEX(BDH($G$9,$H$9,'01_Parametros'!$B$7,'01_Parametros'!$B$7,"Days=A","Fill=B","Dir=H"),1,2),BDH($G$9,$H$9,'01_Parametros'!$B$7,'01_Parametros'!$B$7,"Days=A","Fill=B")) | N9: SOFR 90-day average
A10: 9 | B10: money_market | C10: US | D10: TERM_SOFR_1M | E10: 1M | F10: 0.083 | G10: USOSFR1Z BGN Curncy | H10: PX_LAST | I10: percent | J10: =IFERROR(INDEX(BDH($G$10,$H$10,'01_Parametros'!$B$3,'01_Parametros'!$B$3,"Days=A","Fill=B","Dir=H"),1,2),BDH($G$10,$H$10,'01_Parametros'!$B$3,'01_Parametros'!$B$3,"Days=A","Fill=B")) | K10: =IFERROR(INDEX(BDH($G$10,$H$10,'01_Parametros'!$B$5,'01_Parametros'!$B$5,"Days=A","Fill=B","Dir=H"),1,2),BDH($G$10,$H$10,'01_Parametros'!$B$5,'01_Parametros'!$B$5,"Days=A","Fill=B")) | L10: =IFERROR(INDEX(BDH($G$10,$H$10,'01_Parametros'!$B$6,'01_Parametros'!$B$6,"Days=A","Fill=B","Dir=H"),1,2),BDH($G$10,$H$10,'01_Parametros'!$B$6,'01_Parametros'!$B$6,"Days=A","Fill=B")) | M10: =IFERROR(INDEX(BDH($G$10,$H$10,'01_Parametros'!$B$7,'01_Parametros'!$B$7,"Days=A","Fill=B","Dir=H"),1,2),BDH($G$10,$H$10,'01_Parametros'!$B$7,'01_Parametros'!$B$7,"Days=A","Fill=B")) | N10: Term SOFR 1M - CME
A11: 10 | B11: money_market | C11: US | D11: TERM_SOFR_3M | E11: 3M | F11: 0.25 | G11: USOSFR3Z BGN Curncy | H11: PX_LAST | I11: percent | J11: =IFERROR(INDEX(BDH($G$11,$H$11,'01_Parametros'!$B$3,'01_Parametros'!$B$3,"Days=A","Fill=B","Dir=H"),1,2),BDH($G$11,$H$11,'01_Parametros'!$B$3,'01_Parametros'!$B$3,"Days=A","Fill=B")) | K11: =IFERROR(INDEX(BDH($G$11,$H$11,'01_Parametros'!$B$5,'01_Parametros'!$B$5,"Days=A","Fill=B","Dir=H"),1,2),BDH($G$11,$H$11,'01_Parametros'!$B$5,'01_Parametros'!$B$5,"Days=A","Fill=B")) | L11: =IFERROR(INDEX(BDH($G$11,$H$11,'01_Parametros'!$B$6,'01_Parametros'!$B$6,"Days=A","Fill=B","Dir=H"),1,2),BDH($G$11,$H$11,'01_Parametros'!$B$6,'01_Parametros'!$B$6,"Days=A","Fill=B")) | M11: =IFERROR(INDEX(BDH($G$11,$H$11,'01_Parametros'!$B$7,'01_Parametros'!$B$7,"Days=A","Fill=B","Dir=H"),1,2),BDH($G$11,$H$11,'01_Parametros'!$B$7,'01_Parametros'!$B$7,"Days=A","Fill=B")) | N11: Term SOFR 3M - CME
A12: 11 | B12: money_market | C12: US | D12: TERM_SOFR_6M | E12: 6M | F12: 0.5 | G12: USOSFR6Z BGN Curncy | H12: PX_LAST | I12: percent | J12: =IFERROR(INDEX(BDH($G$12,$H$12,'01_Parametros'!$B$3,'01_Parametros'!$B$3,"Days=A","Fill=B","Dir=H"),1,2),BDH($G$12,$H$12,'01_Parametros'!$B$3,'01_Parametros'!$B$3,"Days=A","Fill=B")) | K12: =IFERROR(INDEX(BDH($G$12,$H$12,'01_Parametros'!$B$5,'01_Parametros'!$B$5,"Days=A","Fill=B","Dir=H"),1,2),BDH($G$12,$H$12,'01_Parametros'!$B$5,'01_Parametros'!$B$5,"Days=A","Fill=B")) | L12: =IFERROR(INDEX(BDH($G$12,$H$12,'01_Parametros'!$B$6,'01_Parametros'!$B$6,"Days=A","Fill=B","Dir=H"),1,2),BDH($G$12,$H$12,'01_Parametros'!$B$6,'01_Parametros'!$B$6,"Days=A","Fill=B")) | M12: =IFERROR(INDEX(BDH($G$12,$H$12,'01_Parametros'!$B$7,'01_Parametros'!$B$7,"Days=A","Fill=B","Dir=H"),1,2),BDH($G$12,$H$12,'01_Parametros'!$B$7,'01_Parametros'!$B$7,"Days=A","Fill=B")) | N12: Term SOFR 6M - CME
A13: 12 | B13: money_market | C13: US | D13: TERM_SOFR_12M | E13: 12M | F13: 1 | G13: USOSFR12Z BGN Curncy | H13: PX_LAST | I13: percent | J13: =IFERROR(INDEX(BDH($G$13,$H$13,'01_Parametros'!$B$3,'01_Parametros'!$B$3,"Days=A","Fill=B","Dir=H"),1,2),BDH($G$13,$H$13,'01_Parametros'!$B$3,'01_Parametros'!$B$3,"Days=A","Fill=B")) | K13: =IFERROR(INDEX(BDH($G$13,$H$13,'01_Parametros'!$B$5,'01_Parametros'!$B$5,"Days=A","Fill=B","Dir=H"),1,2),BDH($G$13,$H$13,'01_Parametros'!$B$5,'01_Parametros'!$B$5,"Days=A","Fill=B")) | L13: =IFERROR(INDEX(BDH($G$13,$H$13,'01_Parametros'!$B$6,'01_Parametros'!$B$6,"Days=A","Fill=B","Dir=H"),1,2),BDH($G$13,$H$13,'01_Parametros'!$B$6,'01_Parametros'!$B$6,"Days=A","Fill=B")) | M13: =IFERROR(INDEX(BDH($G$13,$H$13,'01_Parametros'!$B$7,'01_Parametros'!$B$7,"Days=A","Fill=B","Dir=H"),1,2),BDH($G$13,$H$13,'01_Parametros'!$B$7,'01_Parametros'!$B$7,"Days=A","Fill=B")) | N13: Term SOFR 12M - CME
A14: 13 | B14: yield_curve | C14: US | D14: UST | E14: 1M | F14: 0.083 | G14: USGG1M Index | H14: PX_LAST | I14: percent | J14: =IFERROR(INDEX(BDH($G$14,$H$14,'01_Parametros'!$B$3,'01_Parametros'!$B$3,"Days=A","Fill=B","Dir=H"),1,2),BDH($G$14,$H$14,'01_Parametros'!$B$3,'01_Parametros'!$B$3,"Days=A","Fill=B")) | K14: =IFERROR(INDEX(BDH($G$14,$H$14,'01_Parametros'!$B$5,'01_Parametros'!$B$5,"Days=A","Fill=B","Dir=H"),1,2),BDH($G$14,$H$14,'01_Parametros'!$B$5,'01_Parametros'!$B$5,"Days=A","Fill=B")) | L14: =IFERROR(INDEX(BDH($G$14,$H$14,'01_Parametros'!$B$6,'01_Parametros'!$B$6,"Days=A","Fill=B","Dir=H"),1,2),BDH($G$14,$H$14,'01_Parametros'!$B$6,'01_Parametros'!$B$6,"Days=A","Fill=B")) | M14: =IFERROR(INDEX(BDH($G$14,$H$14,'01_Parametros'!$B$7,'01_Parametros'!$B$7,"Days=A","Fill=B","Dir=H"),1,2),BDH($G$14,$H$14,'01_Parametros'!$B$7,'01_Parametros'!$B$7,"Days=A","Fill=B")) | N14: US Treasury 1M nominal
A15: 14 | B15: yield_curve | C15: US | D15: UST | E15: 3M | F15: 0.25 | G15: USGG3M Index | H15: PX_LAST | I15: percent | J15: =IFERROR(INDEX(BDH($G$15,$H$15,'01_Parametros'!$B$3,'01_Parametros'!$B$3,"Days=A","Fill=B","Dir=H"),1,2),BDH($G$15,$H$15,'01_Parametros'!$B$3,'01_Parametros'!$B$3,"Days=A","Fill=B")) | K15: =IFERROR(INDEX(BDH($G$15,$H$15,'01_Parametros'!$B$5,'01_Parametros'!$B$5,"Days=A","Fill=B","Dir=H"),1,2),BDH($G$15,$H$15,'01_Parametros'!$B$5,'01_Parametros'!$B$5,"Days=A","Fill=B")) | L15: =IFERROR(INDEX(BDH($G$15,$H$15,'01_Parametros'!$B$6,'01_Parametros'!$B$6,"Days=A","Fill=B","Dir=H"),1,2),BDH($G$15,$H$15,'01_Parametros'!$B$6,'01_Parametros'!$B$6,"Days=A","Fill=B")) | M15: =IFERROR(INDEX(BDH($G$15,$H$15,'01_Parametros'!$B$7,'01_Parametros'!$B$7,"Days=A","Fill=B","Dir=H"),1,2),BDH($G$15,$H$15,'01_Parametros'!$B$7,'01_Parametros'!$B$7,"Days=A","Fill=B")) | N15: US Treasury 3M nominal
A16: 15 | B16: yield_curve | C16: US | D16: UST | E16: 6M | F16: 0.5 | G16: USGG6M Index | H16: PX_LAST | I16: percent | J16: =IFERROR(INDEX(BDH($G$16,$H$16,'01_Parametros'!$B$3,'01_Parametros'!$B$3,"Days=A","Fill=B","Dir=H"),1,2),BDH($G$16,$H$16,'01_Parametros'!$B$3,'01_Parametros'!$B$3,"Days=A","Fill=B")) | K16: =IFERROR(INDEX(BDH($G$16,$H$16,'01_Parametros'!$B$5,'01_Parametros'!$B$5,"Days=A","Fill=B","Dir=H"),1,2),BDH($G$16,$H$16,'01_Parametros'!$B$5,'01_Parametros'!$B$5,"Days=A","Fill=B")) | L16: =IFERROR(INDEX(BDH($G$16,$H$16,'01_Parametros'!$B$6,'01_Parametros'!$B$6,"Days=A","Fill=B","Dir=H"),1,2),BDH($G$16,$H$16,'01_Parametros'!$B$6,'01_Parametros'!$B$6,"Days=A","Fill=B")) | M16: =IFERROR(INDEX(BDH($G$16,$H$16,'01_Parametros'!$B$7,'01_Parametros'!$B$7,"Days=A","Fill=B","Dir=H"),1,2),BDH($G$16,$H$16,'01_Parametros'!$B$7,'01_Parametros'!$B$7,"Days=A","Fill=B")) | N16: US Treasury 6M nominal
A17: 16 | B17: yield_curve | C17: US | D17: UST | E17: 1Y | F17: 1 | G17: USGG12M Index | H17: PX_LAST | I17: percent | J17: =IFERROR(INDEX(BDH($G$17,$H$17,'01_Parametros'!$B$3,'01_Parametros'!$B$3,"Days=A","Fill=B","Dir=H"),1,2),BDH($G$17,$H$17,'01_Parametros'!$B$3,'01_Parametros'!$B$3,"Days=A","Fill=B")) | K17: =IFERROR(INDEX(BDH($G$17,$H$17,'01_Parametros'!$B$5,'01_Parametros'!$B$5,"Days=A","Fill=B","Dir=H"),1,2),BDH($G$17,$H$17,'01_Parametros'!$B$5,'01_Parametros'!$B$5,"Days=A","Fill=B")) | L17: =IFERROR(INDEX(BDH($G$17,$H$17,'01_Parametros'!$B$6,'01_Parametros'!$B$6,"Days=A","Fill=B","Dir=H"),1,2),BDH($G$17,$H$17,'01_Parametros'!$B$6,'01_Parametros'!$B$6,"Days=A","Fill=B")) | M17: =IFERROR(INDEX(BDH($G$17,$H$17,'01_Parametros'!$B$7,'01_Parametros'!$B$7,"Days=A","Fill=B","Dir=H"),1,2),BDH($G$17,$H$17,'01_Parametros'!$B$7,'01_Parametros'!$B$7,"Days=A","Fill=B")) | N17: US Treasury 1Y nominal
A18: 17 | B18: yield_curve | C18: US | D18: UST | E18: 2Y | F18: 2 | G18: USGG2YR Index | H18: PX_LAST | I18: percent | J18: =IFERROR(INDEX(BDH($G$18,$H$18,'01_Parametros'!$B$3,'01_Parametros'!$B$3,"Days=A","Fill=B","Dir=H"),1,2),BDH($G$18,$H$18,'01_Parametros'!$B$3,'01_Parametros'!$B$3,"Days=A","Fill=B")) | K18: =IFERROR(INDEX(BDH($G$18,$H$18,'01_Parametros'!$B$5,'01_Parametros'!$B$5,"Days=A","Fill=B","Dir=H"),1,2),BDH($G$18,$H$18,'01_Parametros'!$B$5,'01_Parametros'!$B$5,"Days=A","Fill=B")) | L18: =IFERROR(INDEX(BDH($G$18,$H$18,'01_Parametros'!$B$6,'01_Parametros'!$B$6,"Days=A","Fill=B","Dir=H"),1,2),BDH($G$18,$H$18,'01_Parametros'!$B$6,'01_Parametros'!$B$6,"Days=A","Fill=B")) | M18: =IFERROR(INDEX(BDH($G$18,$H$18,'01_Parametros'!$B$7,'01_Parametros'!$B$7,"Days=A","Fill=B","Dir=H"),1,2),BDH($G$18,$H$18,'01_Parametros'!$B$7,'01_Parametros'!$B$7,"Days=A","Fill=B")) | N18: US Treasury 2Y nominal
A19: 18 | B19: yield_curve | C19: US | D19: UST | E19: 3Y | F19: 3 | G19: USGG3YR Index | H19: PX_LAST | I19: percent | J19: =IFERROR(INDEX(BDH($G$19,$H$19,'01_Parametros'!$B$3,'01_Parametros'!$B$3,"Days=A","Fill=B","Dir=H"),1,2),BDH($G$19,$H$19,'01_Parametros'!$B$3,'01_Parametros'!$B$3,"Days=A","Fill=B")) | K19: =IFERROR(INDEX(BDH($G$19,$H$19,'01_Parametros'!$B$5,'01_Parametros'!$B$5,"Days=A","Fill=B","Dir=H"),1,2),BDH($G$19,$H$19,'01_Parametros'!$B$5,'01_Parametros'!$B$5,"Days=A","Fill=B")) | L19: =IFERROR(INDEX(BDH($G$19,$H$19,'01_Parametros'!$B$6,'01_Parametros'!$B$6,"Days=A","Fill=B","Dir=H"),1,2),BDH($G$19,$H$19,'01_Parametros'!$B$6,'01_Parametros'!$B$6,"Days=A","Fill=B")) | M19: =IFERROR(INDEX(BDH($G$19,$H$19,'01_Parametros'!$B$7,'01_Parametros'!$B$7,"Days=A","Fill=B","Dir=H"),1,2),BDH($G$19,$H$19,'01_Parametros'!$B$7,'01_Parametros'!$B$7,"Days=A","Fill=B")) | N19: US Treasury 3Y nominal
A20: 19 | B20: yield_curve | C20: US | D20: UST | E20: 5Y | F20: 5 | G20: USGG5YR Index | H20: PX_LAST | I20: percent | J20: =IFERROR(INDEX(BDH($G$20,$H$20,'01_Parametros'!$B$3,'01_Parametros'!$B$3,"Days=A","Fill=B","Dir=H"),1,2),BDH($G$20,$H$20,'01_Parametros'!$B$3,'01_Parametros'!$B$3,"Days=A","Fill=B")) | K20: =IFERROR(INDEX(BDH($G$20,$H$20,'01_Parametros'!$B$5,'01_Parametros'!$B$5,"Days=A","Fill=B","Dir=H"),1,2),BDH($G$20,$H$20,'01_Parametros'!$B$5,'01_Parametros'!$B$5,"Days=A","Fill=B")) | L20: =IFERROR(INDEX(BDH($G$20,$H$20,'01_Parametros'!$B$6,'01_Parametros'!$B$6,"Days=A","Fill=B","Dir=H"),1,2),BDH($G$20,$H$20,'01_Parametros'!$B$6,'01_Parametros'!$B$6,"Days=A","Fill=B")) | M20: =IFERROR(INDEX(BDH($G$20,$H$20,'01_Parametros'!$B$7,'01_Parametros'!$B$7,"Days=A","Fill=B","Dir=H"),1,2),BDH($G$20,$H$20,'01_Parametros'!$B$7,'01_Parametros'!$B$7,"Days=A","Fill=B")) | N20: US Treasury 5Y nominal
A21: 20 | B21: yield_curve | C21: US | D21: UST | E21: 7Y | F21: 7 | G21: USGG7YR Index | H21: PX_LAST | I21: percent | J21: =IFERROR(INDEX(BDH($G$21,$H$21,'01_Parametros'!$B$3,'01_Parametros'!$B$3,"Days=A","Fill=B","Dir=H"),1,2),BDH($G$21,$H$21,'01_Parametros'!$B$3,'01_Parametros'!$B$3,"Days=A","Fill=B")) | K21: =IFERROR(INDEX(BDH($G$21,$H$21,'01_Parametros'!$B$5,'01_Parametros'!$B$5,"Days=A","Fill=B","Dir=H"),1,2),BDH($G$21,$H$21,'01_Parametros'!$B$5,'01_Parametros'!$B$5,"Days=A","Fill=B")) | L21: =IFERROR(INDEX(BDH($G$21,$H$21,'01_Parametros'!$B$6,'01_Parametros'!$B$6,"Days=A","Fill=B","Dir=H"),1,2),BDH($G$21,$H$21,'01_Parametros'!$B$6,'01_Parametros'!$B$6,"Days=A","Fill=B")) | M21: =IFERROR(INDEX(BDH($G$21,$H$21,'01_Parametros'!$B$7,'01_Parametros'!$B$7,"Days=A","Fill=B","Dir=H"),1,2),BDH($G$21,$H$21,'01_Parametros'!$B$7,'01_Parametros'!$B$7,"Days=A","Fill=B")) | N21: US Treasury 7Y nominal
A22: 21 | B22: yield_curve | C22: US | D22: UST | E22: 10Y | F22: 10 | G22: USGG10YR Index | H22: PX_LAST | I22: percent | J22: =IFERROR(INDEX(BDH($G$22,$H$22,'01_Parametros'!$B$3,'01_Parametros'!$B$3,"Days=A","Fill=B","Dir=H"),1,2),BDH($G$22,$H$22,'01_Parametros'!$B$3,'01_Parametros'!$B$3,"Days=A","Fill=B")) | K22: =IFERROR(INDEX(BDH($G$22,$H$22,'01_Parametros'!$B$5,'01_Parametros'!$B$5,"Days=A","Fill=B","Dir=H"),1,2),BDH($G$22,$H$22,'01_Parametros'!$B$5,'01_Parametros'!$B$5,"Days=A","Fill=B")) | L22: =IFERROR(INDEX(BDH($G$22,$H$22,'01_Parametros'!$B$6,'01_Parametros'!$B$6,"Days=A","Fill=B","Dir=H"),1,2),BDH($G$22,$H$22,'01_Parametros'!$B$6,'01_Parametros'!$B$6,"Days=A","Fill=B")) | M22: =IFERROR(INDEX(BDH($G$22,$H$22,'01_Parametros'!$B$7,'01_Parametros'!$B$7,"Days=A","Fill=B","Dir=H"),1,2),BDH($G$22,$H$22,'01_Parametros'!$B$7,'01_Parametros'!$B$7,"Days=A","Fill=B")) | N22: US Treasury 10Y nominal
A23: 22 | B23: yield_curve | C23: US | D23: UST | E23: 20Y | F23: 20 | G23: USGG20YR Index | H23: PX_LAST | I23: percent | J23: =IFERROR(INDEX(BDH($G$23,$H$23,'01_Parametros'!$B$3,'01_Parametros'!$B$3,"Days=A","Fill=B","Dir=H"),1,2),BDH($G$23,$H$23,'01_Parametros'!$B$3,'01_Parametros'!$B$3,"Days=A","Fill=B")) | K23: =IFERROR(INDEX(BDH($G$23,$H$23,'01_Parametros'!$B$5,'01_Parametros'!$B$5,"Days=A","Fill=B","Dir=H"),1,2),BDH($G$23,$H$23,'01_Parametros'!$B$5,'01_Parametros'!$B$5,"Days=A","Fill=B")) | L23: =IFERROR(INDEX(BDH($G$23,$H$23,'01_Parametros'!$B$6,'01_Parametros'!$B$6,"Days=A","Fill=B","Dir=H"),1,2),BDH($G$23,$H$23,'01_Parametros'!$B$6,'01_Parametros'!$B$6,"Days=A","Fill=B")) | M23: =IFERROR(INDEX(BDH($G$23,$H$23,'01_Parametros'!$B$7,'01_Parametros'!$B$7,"Days=A","Fill=B","Dir=H"),1,2),BDH($G$23,$H$23,'01_Parametros'!$B$7,'01_Parametros'!$B$7,"Days=A","Fill=B")) | N23: US Treasury 20Y nominal
A24: 23 | B24: yield_curve | C24: US | D24: UST | E24: 30Y | F24: 30 | G24: USGG30YR Index | H24: PX_LAST | I24: percent | J24: =IFERROR(INDEX(BDH($G$24,$H$24,'01_Parametros'!$B$3,'01_Parametros'!$B$3,"Days=A","Fill=B","Dir=H"),1,2),BDH($G$24,$H$24,'01_Parametros'!$B$3,'01_Parametros'!$B$3,"Days=A","Fill=B")) | K24: =IFERROR(INDEX(BDH($G$24,$H$24,'01_Parametros'!$B$5,'01_Parametros'!$B$5,"Days=A","Fill=B","Dir=H"),1,2),BDH($G$24,$H$24,'01_Parametros'!$B$5,'01_Parametros'!$B$5,"Days=A","Fill=B")) | L24: =IFERROR(INDEX(BDH($G$24,$H$24,'01_Parametros'!$B$6,'01_Parametros'!$B$6,"Days=A","Fill=B","Dir=H"),1,2),BDH($G$24,$H$24,'01_Parametros'!$B$6,'01_Parametros'!$B$6,"Days=A","Fill=B")) | M24: =IFERROR(INDEX(BDH($G$24,$H$24,'01_Parametros'!$B$7,'01_Parametros'!$B$7,"Days=A","Fill=B","Dir=H"),1,2),BDH($G$24,$H$24,'01_Parametros'!$B$7,'01_Parametros'!$B$7,"Days=A","Fill=B")) | N24: US Treasury 30Y nominal
A25: 24 | B25: real_curve | C25: US | D25: TIPS | E25: 5Y | F25: 5 | G25: USGGT05Y Index | H25: PX_LAST | I25: percent | J25: =IFERROR(INDEX(BDH($G$25,$H$25,'01_Parametros'!$B$3,'01_Parametros'!$B$3,"Days=A","Fill=B","Dir=H"),1,2),BDH($G$25,$H$25,'01_Parametros'!$B$3,'01_Parametros'!$B$3,"Days=A","Fill=B")) | K25: =IFERROR(INDEX(BDH($G$25,$H$25,'01_Parametros'!$B$5,'01_Parametros'!$B$5,"Days=A","Fill=B","Dir=H"),1,2),BDH($G$25,$H$25,'01_Parametros'!$B$5,'01_Parametros'!$B$5,"Days=A","Fill=B")) | L25: =IFERROR(INDEX(BDH($G$25,$H$25,'01_Parametros'!$B$6,'01_Parametros'!$B$6,"Days=A","Fill=B","Dir=H"),1,2),BDH($G$25,$H$25,'01_Parametros'!$B$6,'01_Parametros'!$B$6,"Days=A","Fill=B")) | M25: =IFERROR(INDEX(BDH($G$25,$H$25,'01_Parametros'!$B$7,'01_Parametros'!$B$7,"Days=A","Fill=B","Dir=H"),1,2),BDH($G$25,$H$25,'01_Parametros'!$B$7,'01_Parametros'!$B$7,"Days=A","Fill=B")) | N25: US TIPS 5Y real yield CMT - confirmar ticker
A26: 25 | B26: real_curve | C26: US | D26: TIPS | E26: 10Y | F26: 10 | G26: USGGT10Y Index | H26: PX_LAST | I26: percent | J26: =IFERROR(INDEX(BDH($G$26,$H$26,'01_Parametros'!$B$3,'01_Parametros'!$B$3,"Days=A","Fill=B","Dir=H"),1,2),BDH($G$26,$H$26,'01_Parametros'!$B$3,'01_Parametros'!$B$3,"Days=A","Fill=B")) | K26: =IFERROR(INDEX(BDH($G$26,$H$26,'01_Parametros'!$B$5,'01_Parametros'!$B$5,"Days=A","Fill=B","Dir=H"),1,2),BDH($G$26,$H$26,'01_Parametros'!$B$5,'01_Parametros'!$B$5,"Days=A","Fill=B")) | L26: =IFERROR(INDEX(BDH($G$26,$H$26,'01_Parametros'!$B$6,'01_Parametros'!$B$6,"Days=A","Fill=B","Dir=H"),1,2),BDH($G$26,$H$26,'01_Parametros'!$B$6,'01_Parametros'!$B$6,"Days=A","Fill=B")) | M26: =IFERROR(INDEX(BDH($G$26,$H$26,'01_Parametros'!$B$7,'01_Parametros'!$B$7,"Days=A","Fill=B","Dir=H"),1,2),BDH($G$26,$H$26,'01_Parametros'!$B$7,'01_Parametros'!$B$7,"Days=A","Fill=B")) | N26: US TIPS 10Y real yield CMT - confirmar ticker
A27: 26 | B27: real_curve | C27: US | D27: TIPS | E27: 20Y | F27: 20 | G27: USGGT20Y Index | H27: PX_LAST | I27: percent | J27: =IFERROR(INDEX(BDH($G$27,$H$27,'01_Parametros'!$B$3,'01_Parametros'!$B$3,"Days=A","Fill=B","Dir=H"),1,2),BDH($G$27,$H$27,'01_Parametros'!$B$3,'01_Parametros'!$B$3,"Days=A","Fill=B")) | K27: =IFERROR(INDEX(BDH($G$27,$H$27,'01_Parametros'!$B$5,'01_Parametros'!$B$5,"Days=A","Fill=B","Dir=H"),1,2),BDH($G$27,$H$27,'01_Parametros'!$B$5,'01_Parametros'!$B$5,"Days=A","Fill=B")) | L27: =IFERROR(INDEX(BDH($G$27,$H$27,'01_Parametros'!$B$6,'01_Parametros'!$B$6,"Days=A","Fill=B","Dir=H"),1,2),BDH($G$27,$H$27,'01_Parametros'!$B$6,'01_Parametros'!$B$6,"Days=A","Fill=B")) | M27: =IFERROR(INDEX(BDH($G$27,$H$27,'01_Parametros'!$B$7,'01_Parametros'!$B$7,"Days=A","Fill=B","Dir=H"),1,2),BDH($G$27,$H$27,'01_Parametros'!$B$7,'01_Parametros'!$B$7,"Days=A","Fill=B")) | N27: US TIPS 20Y real yield CMT - confirmar ticker
A28: 27 | B28: real_curve | C28: US | D28: TIPS | E28: 30Y | F28: 30 | G28: USGGT30Y Index | H28: PX_LAST | I28: percent | J28: =IFERROR(INDEX(BDH($G$28,$H$28,'01_Parametros'!$B$3,'01_Parametros'!$B$3,"Days=A","Fill=B","Dir=H"),1,2),BDH($G$28,$H$28,'01_Parametros'!$B$3,'01_Parametros'!$B$3,"Days=A","Fill=B")) | K28: =IFERROR(INDEX(BDH($G$28,$H$28,'01_Parametros'!$B$5,'01_Parametros'!$B$5,"Days=A","Fill=B","Dir=H"),1,2),BDH($G$28,$H$28,'01_Parametros'!$B$5,'01_Parametros'!$B$5,"Days=A","Fill=B")) | L28: =IFERROR(INDEX(BDH($G$28,$H$28,'01_Parametros'!$B$6,'01_Parametros'!$B$6,"Days=A","Fill=B","Dir=H"),1,2),BDH($G$28,$H$28,'01_Parametros'!$B$6,'01_Parametros'!$B$6,"Days=A","Fill=B")) | M28: =IFERROR(INDEX(BDH($G$28,$H$28,'01_Parametros'!$B$7,'01_Parametros'!$B$7,"Days=A","Fill=B","Dir=H"),1,2),BDH($G$28,$H$28,'01_Parametros'!$B$7,'01_Parametros'!$B$7,"Days=A","Fill=B")) | N28: US TIPS 30Y real yield CMT - confirmar ticker
A29: 28 | B29: breakeven | C29: US | D29: BE_INFL | E29: 2Y | F29: 2 | G29: USGGBE02 Index | H29: PX_LAST | I29: percent | J29: =IFERROR(INDEX(BDH($G$29,$H$29,'01_Parametros'!$B$3,'01_Parametros'!$B$3,"Days=A","Fill=B","Dir=H"),1,2),BDH($G$29,$H$29,'01_Parametros'!$B$3,'01_Parametros'!$B$3,"Days=A","Fill=B")) | K29: =IFERROR(INDEX(BDH($G$29,$H$29,'01_Parametros'!$B$5,'01_Parametros'!$B$5,"Days=A","Fill=B","Dir=H"),1,2),BDH($G$29,$H$29,'01_Parametros'!$B$5,'01_Parametros'!$B$5,"Days=A","Fill=B")) | L29: =IFERROR(INDEX(BDH($G$29,$H$29,'01_Parametros'!$B$6,'01_Parametros'!$B$6,"Days=A","Fill=B","Dir=H"),1,2),BDH($G$29,$H$29,'01_Parametros'!$B$6,'01_Parametros'!$B$6,"Days=A","Fill=B")) | M29: =IFERROR(INDEX(BDH($G$29,$H$29,'01_Parametros'!$B$7,'01_Parametros'!$B$7,"Days=A","Fill=B","Dir=H"),1,2),BDH($G$29,$H$29,'01_Parametros'!$B$7,'01_Parametros'!$B$7,"Days=A","Fill=B")) | N29: US 2Y breakeven inflation
A30: 29 | B30: breakeven | C30: US | D30: BE_INFL | E30: 5Y | F30: 5 | G30: USGGBE05 Index | H30: PX_LAST | I30: percent | J30: =IFERROR(INDEX(BDH($G$30,$H$30,'01_Parametros'!$B$3,'01_Parametros'!$B$3,"Days=A","Fill=B","Dir=H"),1,2),BDH($G$30,$H$30,'01_Parametros'!$B$3,'01_Parametros'!$B$3,"Days=A","Fill=B")) | K30: =IFERROR(INDEX(BDH($G$30,$H$30,'01_Parametros'!$B$5,'01_Parametros'!$B$5,"Days=A","Fill=B","Dir=H"),1,2),BDH($G$30,$H$30,'01_Parametros'!$B$5,'01_Parametros'!$B$5,"Days=A","Fill=B")) | L30: =IFERROR(INDEX(BDH($G$30,$H$30,'01_Parametros'!$B$6,'01_Parametros'!$B$6,"Days=A","Fill=B","Dir=H"),1,2),BDH($G$30,$H$30,'01_Parametros'!$B$6,'01_Parametros'!$B$6,"Days=A","Fill=B")) | M30: =IFERROR(INDEX(BDH($G$30,$H$30,'01_Parametros'!$B$7,'01_Parametros'!$B$7,"Days=A","Fill=B","Dir=H"),1,2),BDH($G$30,$H$30,'01_Parametros'!$B$7,'01_Parametros'!$B$7,"Days=A","Fill=B")) | N30: US 5Y breakeven inflation
A31: 30 | B31: breakeven | C31: US | D31: BE_INFL | E31: 10Y | F31: 10 | G31: USGGBE10 Index | H31: PX_LAST | I31: percent | J31: =IFERROR(INDEX(BDH($G$31,$H$31,'01_Parametros'!$B$3,'01_Parametros'!$B$3,"Days=A","Fill=B","Dir=H"),1,2),BDH($G$31,$H$31,'01_Parametros'!$B$3,'01_Parametros'!$B$3,"Days=A","Fill=B")) | K31: =IFERROR(INDEX(BDH($G$31,$H$31,'01_Parametros'!$B$5,'01_Parametros'!$B$5,"Days=A","Fill=B","Dir=H"),1,2),BDH($G$31,$H$31,'01_Parametros'!$B$5,'01_Parametros'!$B$5,"Days=A","Fill=B")) | L31: =IFERROR(INDEX(BDH($G$31,$H$31,'01_Parametros'!$B$6,'01_Parametros'!$B$6,"Days=A","Fill=B","Dir=H"),1,2),BDH($G$31,$H$31,'01_Parametros'!$B$6,'01_Parametros'!$B$6,"Days=A","Fill=B")) | M31: =IFERROR(INDEX(BDH($G$31,$H$31,'01_Parametros'!$B$7,'01_Parametros'!$B$7,"Days=A","Fill=B","Dir=H"),1,2),BDH($G$31,$H$31,'01_Parametros'!$B$7,'01_Parametros'!$B$7,"Days=A","Fill=B")) | N31: US 10Y breakeven inflation
A32: 31 | B32: breakeven | C32: US | D32: BE_INFL | E32: 30Y | F32: 30 | G32: USGGBE30 Index | H32: PX_LAST | I32: percent | J32: =IFERROR(INDEX(BDH($G$32,$H$32,'01_Parametros'!$B$3,'01_Parametros'!$B$3,"Days=A","Fill=B","Dir=H"),1,2),BDH($G$32,$H$32,'01_Parametros'!$B$3,'01_Parametros'!$B$3,"Days=A","Fill=B")) | K32: =IFERROR(INDEX(BDH($G$32,$H$32,'01_Parametros'!$B$5,'01_Parametros'!$B$5,"Days=A","Fill=B","Dir=H"),1,2),BDH($G$32,$H$32,'01_Parametros'!$B$5,'01_Parametros'!$B$5,"Days=A","Fill=B")) | L32: =IFERROR(INDEX(BDH($G$32,$H$32,'01_Parametros'!$B$6,'01_Parametros'!$B$6,"Days=A","Fill=B","Dir=H"),1,2),BDH($G$32,$H$32,'01_Parametros'!$B$6,'01_Parametros'!$B$6,"Days=A","Fill=B")) | M32: =IFERROR(INDEX(BDH($G$32,$H$32,'01_Parametros'!$B$7,'01_Parametros'!$B$7,"Days=A","Fill=B","Dir=H"),1,2),BDH($G$32,$H$32,'01_Parametros'!$B$7,'01_Parametros'!$B$7,"Days=A","Fill=B")) | N32: US 30Y breakeven inflation
A33: 32 | B33: swap_curve | C33: US | D33: SOFR_OIS | E33: 2Y | F33: 2 | G33: USOSFR2 BGN Curncy | H33: PX_LAST | I33: percent | J33: =IFERROR(INDEX(BDH($G$33,$H$33,'01_Parametros'!$B$3,'01_Parametros'!$B$3,"Days=A","Fill=B","Dir=H"),1,2),BDH($G$33,$H$33,'01_Parametros'!$B$3,'01_Parametros'!$B$3,"Days=A","Fill=B")) | K33: =IFERROR(INDEX(BDH($G$33,$H$33,'01_Parametros'!$B$5,'01_Parametros'!$B$5,"Days=A","Fill=B","Dir=H"),1,2),BDH($G$33,$H$33,'01_Parametros'!$B$5,'01_Parametros'!$B$5,"Days=A","Fill=B")) | L33: =IFERROR(INDEX(BDH($G$33,$H$33,'01_Parametros'!$B$6,'01_Parametros'!$B$6,"Days=A","Fill=B","Dir=H"),1,2),BDH($G$33,$H$33,'01_Parametros'!$B$6,'01_Parametros'!$B$6,"Days=A","Fill=B")) | M33: =IFERROR(INDEX(BDH($G$33,$H$33,'01_Parametros'!$B$7,'01_Parametros'!$B$7,"Days=A","Fill=B","Dir=H"),1,2),BDH($G$33,$H$33,'01_Parametros'!$B$7,'01_Parametros'!$B$7,"Days=A","Fill=B")) | N33: USD SOFR OIS 2Y - confirmar convencion
A34: 33 | B34: swap_curve | C34: US | D34: SOFR_OIS | E34: 5Y | F34: 5 | G34: USOSFR5 BGN Curncy | H34: PX_LAST | I34: percent | J34: =IFERROR(INDEX(BDH($G$34,$H$34,'01_Parametros'!$B$3,'01_Parametros'!$B$3,"Days=A","Fill=B","Dir=H"),1,2),BDH($G$34,$H$34,'01_Parametros'!$B$3,'01_Parametros'!$B$3,"Days=A","Fill=B")) | K34: =IFERROR(INDEX(BDH($G$34,$H$34,'01_Parametros'!$B$5,'01_Parametros'!$B$5,"Days=A","Fill=B","Dir=H"),1,2),BDH($G$34,$H$34,'01_Parametros'!$B$5,'01_Parametros'!$B$5,"Days=A","Fill=B")) | L34: =IFERROR(INDEX(BDH($G$34,$H$34,'01_Parametros'!$B$6,'01_Parametros'!$B$6,"Days=A","Fill=B","Dir=H"),1,2),BDH($G$34,$H$34,'01_Parametros'!$B$6,'01_Parametros'!$B$6,"Days=A","Fill=B")) | M34: =IFERROR(INDEX(BDH($G$34,$H$34,'01_Parametros'!$B$7,'01_Parametros'!$B$7,"Days=A","Fill=B","Dir=H"),1,2),BDH($G$34,$H$34,'01_Parametros'!$B$7,'01_Parametros'!$B$7,"Days=A","Fill=B")) | N34: USD SOFR OIS 5Y - confirmar convencion
A35: 34 | B35: swap_curve | C35: US | D35: SOFR_OIS | E35: 10Y | F35: 10 | G35: USOSFR10 BGN Curncy | H35: PX_LAST | I35: percent | J35: =IFERROR(INDEX(BDH($G$35,$H$35,'01_Parametros'!$B$3,'01_Parametros'!$B$3,"Days=A","Fill=B","Dir=H"),1,2),BDH($G$35,$H$35,'01_Parametros'!$B$3,'01_Parametros'!$B$3,"Days=A","Fill=B")) | K35: =IFERROR(INDEX(BDH($G$35,$H$35,'01_Parametros'!$B$5,'01_Parametros'!$B$5,"Days=A","Fill=B","Dir=H"),1,2),BDH($G$35,$H$35,'01_Parametros'!$B$5,'01_Parametros'!$B$5,"Days=A","Fill=B")) | L35: =IFERROR(INDEX(BDH($G$35,$H$35,'01_Parametros'!$B$6,'01_Parametros'!$B$6,"Days=A","Fill=B","Dir=H"),1,2),BDH($G$35,$H$35,'01_Parametros'!$B$6,'01_Parametros'!$B$6,"Days=A","Fill=B")) | M35: =IFERROR(INDEX(BDH($G$35,$H$35,'01_Parametros'!$B$7,'01_Parametros'!$B$7,"Days=A","Fill=B","Dir=H"),1,2),BDH($G$35,$H$35,'01_Parametros'!$B$7,'01_Parametros'!$B$7,"Days=A","Fill=B")) | N35: USD SOFR OIS 10Y - confirmar convencion
A36: 35 | B36: swap_curve | C36: US | D36: SOFR_OIS | E36: 30Y | F36: 30 | G36: USOSFR30 BGN Curncy | H36: PX_LAST | I36: percent | J36: =IFERROR(INDEX(BDH($G$36,$H$36,'01_Parametros'!$B$3,'01_Parametros'!$B$3,"Days=A","Fill=B","Dir=H"),1,2),BDH($G$36,$H$36,'01_Parametros'!$B$3,'01_Parametros'!$B$3,"Days=A","Fill=B")) | K36: =IFERROR(INDEX(BDH($G$36,$H$36,'01_Parametros'!$B$5,'01_Parametros'!$B$5,"Days=A","Fill=B","Dir=H"),1,2),BDH($G$36,$H$36,'01_Parametros'!$B$5,'01_Parametros'!$B$5,"Days=A","Fill=B")) | L36: =IFERROR(INDEX(BDH($G$36,$H$36,'01_Parametros'!$B$6,'01_Parametros'!$B$6,"Days=A","Fill=B","Dir=H"),1,2),BDH($G$36,$H$36,'01_Parametros'!$B$6,'01_Parametros'!$B$6,"Days=A","Fill=B")) | M36: =IFERROR(INDEX(BDH($G$36,$H$36,'01_Parametros'!$B$7,'01_Parametros'!$B$7,"Days=A","Fill=B","Dir=H"),1,2),BDH($G$36,$H$36,'01_Parametros'!$B$7,'01_Parametros'!$B$7,"Days=A","Fill=B")) | N36: USD SOFR OIS 30Y - confirmar convencion
A37: 36 | B37: policy | C37: EU | D37: ECB_DFR | E37: — | F37: 0 | G37: EURR002W Index | H37: PX_LAST | I37: percent | J37: =IFERROR(INDEX(BDH($G$37,$H$37,'01_Parametros'!$B$3,'01_Parametros'!$B$3,"Days=A","Fill=B","Dir=H"),1,2),BDH($G$37,$H$37,'01_Parametros'!$B$3,'01_Parametros'!$B$3,"Days=A","Fill=B")) | K37: =IFERROR(INDEX(BDH($G$37,$H$37,'01_Parametros'!$B$5,'01_Parametros'!$B$5,"Days=A","Fill=B","Dir=H"),1,2),BDH($G$37,$H$37,'01_Parametros'!$B$5,'01_Parametros'!$B$5,"Days=A","Fill=B")) | L37: =IFERROR(INDEX(BDH($G$37,$H$37,'01_Parametros'!$B$6,'01_Parametros'!$B$6,"Days=A","Fill=B","Dir=H"),1,2),BDH($G$37,$H$37,'01_Parametros'!$B$6,'01_Parametros'!$B$6,"Days=A","Fill=B")) | M37: =IFERROR(INDEX(BDH($G$37,$H$37,'01_Parametros'!$B$7,'01_Parametros'!$B$7,"Days=A","Fill=B","Dir=H"),1,2),BDH($G$37,$H$37,'01_Parametros'!$B$7,'01_Parametros'!$B$7,"Days=A","Fill=B")) | N37: ECB Deposit Facility Rate
A38: 37 | B38: policy | C38: EU | D38: ECB_MRO | E38: — | F38: 0 | G38: EURMR1WI Index | H38: PX_LAST | I38: percent | J38: =IFERROR(INDEX(BDH($G$38,$H$38,'01_Parametros'!$B$3,'01_Parametros'!$B$3,"Days=A","Fill=B","Dir=H"),1,2),BDH($G$38,$H$38,'01_Parametros'!$B$3,'01_Parametros'!$B$3,"Days=A","Fill=B")) | K38: =IFERROR(INDEX(BDH($G$38,$H$38,'01_Parametros'!$B$5,'01_Parametros'!$B$5,"Days=A","Fill=B","Dir=H"),1,2),BDH($G$38,$H$38,'01_Parametros'!$B$5,'01_Parametros'!$B$5,"Days=A","Fill=B")) | L38: =IFERROR(INDEX(BDH($G$38,$H$38,'01_Parametros'!$B$6,'01_Parametros'!$B$6,"Days=A","Fill=B","Dir=H"),1,2),BDH($G$38,$H$38,'01_Parametros'!$B$6,'01_Parametros'!$B$6,"Days=A","Fill=B")) | M38: =IFERROR(INDEX(BDH($G$38,$H$38,'01_Parametros'!$B$7,'01_Parametros'!$B$7,"Days=A","Fill=B","Dir=H"),1,2),BDH($G$38,$H$38,'01_Parametros'!$B$7,'01_Parametros'!$B$7,"Days=A","Fill=B")) | N38: ECB Main Refi Operations — confirmar ticker
A39: 38 | B39: policy | C39: GB | D39: BOE_BANK_RATE | E39: — | F39: 0 | G39: UKBRBASE Index | H39: PX_LAST | I39: percent | J39: =IFERROR(INDEX(BDH($G$39,$H$39,'01_Parametros'!$B$3,'01_Parametros'!$B$3,"Days=A","Fill=B","Dir=H"),1,2),BDH($G$39,$H$39,'01_Parametros'!$B$3,'01_Parametros'!$B$3,"Days=A","Fill=B")) | K39: =IFERROR(INDEX(BDH($G$39,$H$39,'01_Parametros'!$B$5,'01_Parametros'!$B$5,"Days=A","Fill=B","Dir=H"),1,2),BDH($G$39,$H$39,'01_Parametros'!$B$5,'01_Parametros'!$B$5,"Days=A","Fill=B")) | L39: =IFERROR(INDEX(BDH($G$39,$H$39,'01_Parametros'!$B$6,'01_Parametros'!$B$6,"Days=A","Fill=B","Dir=H"),1,2),BDH($G$39,$H$39,'01_Parametros'!$B$6,'01_Parametros'!$B$6,"Days=A","Fill=B")) | M39: =IFERROR(INDEX(BDH($G$39,$H$39,'01_Parametros'!$B$7,'01_Parametros'!$B$7,"Days=A","Fill=B","Dir=H"),1,2),BDH($G$39,$H$39,'01_Parametros'!$B$7,'01_Parametros'!$B$7,"Days=A","Fill=B")) | N39: BoE Bank Rate
A40: 39 | B40: policy | C40: JP | D40: BOJ_POLICY | E40: — | F40: 0 | G40: BOJDPBAL Index | H40: PX_LAST | I40: percent | J40: =IFERROR(INDEX(BDH($G$40,$H$40,'01_Parametros'!$B$3,'01_Parametros'!$B$3,"Days=A","Fill=B","Dir=H"),1,2),BDH($G$40,$H$40,'01_Parametros'!$B$3,'01_Parametros'!$B$3,"Days=A","Fill=B")) | K40: =IFERROR(INDEX(BDH($G$40,$H$40,'01_Parametros'!$B$5,'01_Parametros'!$B$5,"Days=A","Fill=B","Dir=H"),1,2),BDH($G$40,$H$40,'01_Parametros'!$B$5,'01_Parametros'!$B$5,"Days=A","Fill=B")) | L40: =IFERROR(INDEX(BDH($G$40,$H$40,'01_Parametros'!$B$6,'01_Parametros'!$B$6,"Days=A","Fill=B","Dir=H"),1,2),BDH($G$40,$H$40,'01_Parametros'!$B$6,'01_Parametros'!$B$6,"Days=A","Fill=B")) | M40: =IFERROR(INDEX(BDH($G$40,$H$40,'01_Parametros'!$B$7,'01_Parametros'!$B$7,"Days=A","Fill=B","Dir=H"),1,2),BDH($G$40,$H$40,'01_Parametros'!$B$7,'01_Parametros'!$B$7,"Days=A","Fill=B")) | N40: BoJ policy rate
...

Sheet 03_SOFR_Futures
A1: # | B1: contract_code | C1: description | D1: AS_OF_price | E1: AS_OF_implied_rate | F1: MES_ANT_price | G1: MES_ANT_implied_rate | H1: open_interest
A2: 1 | B2: SFR1 Comdty | C2: SOFR future month 1 | D2: =IFERROR(INDEX(BDH($B$2,"PX_LAST",'01_Parametros'!$B$3,'01_Parametros'!$B$3,"Days=A","Fill=B"),1,2),BDH($B$2,"PX_LAST",'01_Parametros'!$B$3,'01_Parametros'!$B$3,"Days=A","Fill=B")) | E2: =100-D2 | F2: =IFERROR(INDEX(BDH($B$2,"PX_LAST",'01_Parametros'!$B$5,'01_Parametros'!$B$5,"Days=A","Fill=B"),1,2),BDH($B$2,"PX_LAST",'01_Parametros'!$B$5,'01_Parametros'!$B$5,"Days=A","Fill=B")) | G2: =100-F2 | H2: =IFERROR(INDEX(BDH($B$2,"OPEN_INT",'01_Parametros'!$B$3,'01_Parametros'!$B$3,"Days=A","Fill=B"),1,2),BDH($B$2,"OPEN_INT",'01_Parametros'!$B$3,'01_Parametros'!$B$3,"Days=A","Fill=B"))
A3: 2 | B3: SFR2 Comdty | C3: SOFR future month 2 | D3: =IFERROR(INDEX(BDH($B$3,"PX_LAST",'01_Parametros'!$B$3,'01_Parametros'!$B$3,"Days=A","Fill=B"),1,2),BDH($B$3,"PX_LAST",'01_Parametros'!$B$3,'01_Parametros'!$B$3,"Days=A","Fill=B")) | E3: =100-D3 | F3: =IFERROR(INDEX(BDH($B$3,"PX_LAST",'01_Parametros'!$B$5,'01_Parametros'!$B$5,"Days=A","Fill=B"),1,2),BDH($B$3,"PX_LAST",'01_Parametros'!$B$5,'01_Parametros'!$B$5,"Days=A","Fill=B")) | G3: =100-F3 | H3: =IFERROR(INDEX(BDH($B$3,"OPEN_INT",'01_Parametros'!$B$3,'01_Parametros'!$B$3,"Days=A","Fill=B"),1,2),BDH($B$3,"OPEN_INT",'01_Parametros'!$B$3,'01_Parametros'!$B$3,"Days=A","Fill=B"))
A4: 3 | B4: SFR3 Comdty | C4: SOFR future month 3 | D4: =IFERROR(INDEX(BDH($B$4,"PX_LAST",'01_Parametros'!$B$3,'01_Parametros'!$B$3,"Days=A","Fill=B"),1,2),BDH($B$4,"PX_LAST",'01_Parametros'!$B$3,'01_Parametros'!$B$3,"Days=A","Fill=B")) | E4: =100-D4 | F4: =IFERROR(INDEX(BDH($B$4,"PX_LAST",'01_Parametros'!$B$5,'01_Parametros'!$B$5,"Days=A","Fill=B"),1,2),BDH($B$4,"PX_LAST",'01_Parametros'!$B$5,'01_Parametros'!$B$5,"Days=A","Fill=B")) | G4: =100-F4 | H4: =IFERROR(INDEX(BDH($B$4,"OPEN_INT",'01_Parametros'!$B$3,'01_Parametros'!$B$3,"Days=A","Fill=B"),1,2),BDH($B$4,"OPEN_INT",'01_Parametros'!$B$3,'01_Parametros'!$B$3,"Days=A","Fill=B"))
A5: 4 | B5: SFR4 Comdty | C5: SOFR future month 4 | D5: =IFERROR(INDEX(BDH($B$5,"PX_LAST",'01_Parametros'!$B$3,'01_Parametros'!$B$3,"Days=A","Fill=B"),1,2),BDH($B$5,"PX_LAST",'01_Parametros'!$B$3,'01_Parametros'!$B$3,"Days=A","Fill=B")) | E5: =100-D5 | F5: =IFERROR(INDEX(BDH($B$5,"PX_LAST",'01_Parametros'!$B$5,'01_Parametros'!$B$5,"Days=A","Fill=B"),1,2),BDH($B$5,"PX_LAST",'01_Parametros'!$B$5,'01_Parametros'!$B$5,"Days=A","Fill=B")) | G5: =100-F5 | H5: =IFERROR(INDEX(BDH($B$5,"OPEN_INT",'01_Parametros'!$B$3,'01_Parametros'!$B$3,"Days=A","Fill=B"),1,2),BDH($B$5,"OPEN_INT",'01_Parametros'!$B$3,'01_Parametros'!$B$3,"Days=A","Fill=B"))
A6: 5 | B6: SFR5 Comdty | C6: SOFR future month 5 | D6: =IFERROR(INDEX(BDH($B$6,"PX_LAST",'01_Parametros'!$B$3,'01_Parametros'!$B$3,"Days=A","Fill=B"),1,2),BDH($B$6,"PX_LAST",'01_Parametros'!$B$3,'01_Parametros'!$B$3,"Days=A","Fill=B")) | E6: =100-D6 | F6: =IFERROR(INDEX(BDH($B$6,"PX_LAST",'01_Parametros'!$B$5,'01_Parametros'!$B$5,"Days=A","Fill=B"),1,2),BDH($B$6,"PX_LAST",'01_Parametros'!$B$5,'01_Parametros'!$B$5,"Days=A","Fill=B")) | G6: =100-F6 | H6: =IFERROR(INDEX(BDH($B$6,"OPEN_INT",'01_Parametros'!$B$3,'01_Parametros'!$B$3,"Days=A","Fill=B"),1,2),BDH($B$6,"OPEN_INT",'01_Parametros'!$B$3,'01_Parametros'!$B$3,"Days=A","Fill=B"))
A7: 6 | B7: SFR6 Comdty | C7: SOFR future month 6 | D7: =IFERROR(INDEX(BDH($B$7,"PX_LAST",'01_Parametros'!$B$3,'01_Parametros'!$B$3,"Days=A","Fill=B"),1,2),BDH($B$7,"PX_LAST",'01_Parametros'!$B$3,'01_Parametros'!$B$3,"Days=A","Fill=B")) | E7: =100-D7 | F7: =IFERROR(INDEX(BDH($B$7,"PX_LAST",'01_Parametros'!$B$5,'01_Parametros'!$B$5,"Days=A","Fill=B"),1,2),BDH($B$7,"PX_LAST",'01_Parametros'!$B$5,'01_Parametros'!$B$5,"Days=A","Fill=B")) | G7: =100-F7 | H7: =IFERROR(INDEX(BDH($B$7,"OPEN_INT",'01_Parametros'!$B$3,'01_Parametros'!$B$3,"Days=A","Fill=B"),1,2),BDH($B$7,"OPEN_INT",'01_Parametros'!$B$3,'01_Parametros'!$B$3,"Days=A","Fill=B"))
A8: 7 | B8: SFR7 Comdty | C8: SOFR future month 7 | D8: =IFERROR(INDEX(BDH($B$8,"PX_LAST",'01_Parametros'!$B$3,'01_Parametros'!$B$3,"Days=A","Fill=B"),1,2),BDH($B$8,"PX_LAST",'01_Parametros'!$B$3,'01_Parametros'!$B$3,"Days=A","Fill=B")) | E8: =100-D8 | F8: =IFERROR(INDEX(BDH($B$8,"PX_LAST",'01_Parametros'!$B$5,'01_Parametros'!$B$5,"Days=A","Fill=B"),1,2),BDH($B$8,"PX_LAST",'01_Parametros'!$B$5,'01_Parametros'!$B$5,"Days=A","Fill=B")) | G8: =100-F8 | H8: =IFERROR(INDEX(BDH($B$8,"OPEN_INT",'01_Parametros'!$B$3,'01_Parametros'!$B$3,"Days=A","Fill=B"),1,2),BDH($B$8,"OPEN_INT",'01_Parametros'!$B$3,'01_Parametros'!$B$3,"Days=A","Fill=B"))
A9: 8 | B9: SFR8 Comdty | C9: SOFR future month 8 | D9: =IFERROR(INDEX(BDH($B$9,"PX_LAST",'01_Parametros'!$B$3,'01_Parametros'!$B$3,"Days=A","Fill=B"),1,2),BDH($B$9,"PX_LAST",'01_Parametros'!$B$3,'01_Parametros'!$B$3,"Days=A","Fill=B")) | E9: =100-D9 | F9: =IFERROR(INDEX(BDH($B$9,"PX_LAST",'01_Parametros'!$B$5,'01_Parametros'!$B$5,"Days=A","Fill=B"),1,2),BDH($B$9,"PX_LAST",'01_Parametros'!$B$5,'01_Parametros'!$B$5,"Days=A","Fill=B")) | G9: =100-F9 | H9: =IFERROR(INDEX(BDH($B$9,"OPEN_INT",'01_Parametros'!$B$3,'01_Parametros'!$B$3,"Days=A","Fill=B"),1,2),BDH($B$9,"OPEN_INT",'01_Parametros'!$B$3,'01_Parametros'!$B$3,"Days=A","Fill=B"))
A12: Nota | B12: SFRn Comdty = continuous front-month rolling future n (n=1 es el primer vencimiento activo).
B13: Implied rate = 100 - price (convencion CME).
B14: Si el ticker continuous no esta disponible, sustituir por el codigo del contrato especifico (ej. SFRZ6 Comdty para dic-2026).

Sheet 04_FedWatch
A1: FedWatch — paste manual desde pantalla WIRP de Bloomberg
A2: Pegar como valores. Esta hoja NO tiene formulas BDP.
A4: meeting_date | B4: current_rate_implied | C4: prob_-50bps | D4: prob_-25bps | E4: prob_0bps | F4: prob_+25bps | G4: prob_+50bps | H4: notas

Sheet 05_Notas_Analista
A1: Notas del analista
A3: Cualquier observacion: tickers que fallaron, eventos del mes, anomalias, sugerencias.
A5: Tickers fallidos / corregidos
A6: —
A7: —
A8: —
A9: —
A10: —
A11: —
A12: —
A13: —
A14: —
... A29: Sugerencias para el corte siguiente

Sheet 99_Envio
A1: Como devolver este archivo
A3: OPCION 1 — Recomendada — Upload directo a GitHub (web)
A4: 1. Guardar el archivo con nombre: BloombergTemplate_TasasMercantil_<YYYY-MM>.xlsx
A5: 2. En el navegador (incluido movil) ir a: github.com/andresborrerom/credito_Panama
A6: 3. Cambiar al branch: claude/tasas-mercantil-report-Q8sFt
A7: 4. Navegar a la carpeta: ProyectoTasasMercantil/cortes/<YYYY-MM>/input/
A8: (si no existe, crearla con 'Add file -> Create new file' y nombre 'input/.gitkeep')
A9: 5. 'Add file' -> 'Upload files' -> arrastrar el xlsx
A10: 6. Commit message sugerido: 'ingest(corte YYYY-MM): input Bloomberg cargado por <analista>'
A11: 7. Click 'Commit changes'.
A13: OPCION 2 — Correo electronico
A14: Enviar el .xlsx por correo al equipo (Andres + Camilo + Claude session si aplica).
... A24: Si el archivo paso validacion, llega confirmacion. Si fallo, llega lista de campos a revisar.
